Workbook

Sheet 통계표
A1: 이 범위의 담당자별 처리 현황
A2: 2026-10-04 00:35:08 (한국 시간)에 내려받은 결과입니다. 조건은 ‘조회 조건’ 시트에 있습니다.
C4: 건수 | D4: 건수 | E4: 건수 | F4: 건수 | G4: 건수 | H4: 건수 | I4: 건수 | J4: 건수 | K4: 비율 | L4: 비율 | M4: 비율 | N4: 비율 | O4: 비율
A5: 담당자 | B5: 소속 기관 | C5: 건수 · 답변 | D5: 건수 · 분류된 답변 | E5: 건수 · 미분류 | F5: 건수 · 수용 | G5: 건수 · 일부 수용 | H5: 건수 · 불수용 | I5: 건수 · 과태료 처분 | J5: 건수 · 과태료 외 처분 | K5: 비율 · 수용률 | L5: 비율 · 일부수용률 | M5: 비율 · 불수용률 | N5: 비율 · 과태료 부과율 | O5: 비율 · 과태료 외 비율
A6: 김하늘 (서울중부경찰서) | B6: 예시 서울중부경찰서 | C6: 37 | D6: 29 | E6: 8 | F6: 19 | G6: 6 | H6: 4 | I6: 12 | J6: 25 | K6: =F6/D6 -> 0.6551724137931034 | L6: =G6/D6 -> 0.20689655172413793 | M6: =H6/D6 -> 0.13793103448275862 | N6: =I6/C6 -> 0.32432432432432434 | O6: =J6/C6 -> 0.6756756756756757
A7: 정하은 | B7: 예시 수원시청 | C7: 35 | D7: 30 | E7: 5 | F7: 20 | G7: 3 | H7: 7 | I7: 9 | J7: 26 | K7: =F7/D7 -> 0.6666666666666666 | L7: =G7/D7 -> 0.1 | M7: =H7/D7 -> 0.23333333333333334 | N7: =I7/C7 -> 0.2571428571428571 | O7: =J7/C7 -> 0.7428571428571429
A8: 이서윤 | B8: 예시 강남구청 | C8: 34 | D8: 30 | E8: 4 | F8: 22 | G8: 1 | H8: 7 | I8: 9 | J8: 25 | K8: =F8/D8 -> 0.7333333333333333 | L8: =G8/D8 -> 0.03333333333333333 | M8: =H8/D8 -> 0.23333333333333334 | N8: =I8/C8 -> 0.2647058823529412 | O8: =J8/C8 -> 0.7352941176470589
A9: 박도윤 | B9: 예시 서울중부경찰서 | C9: 27 | D9: 24 | E9: 3 | F9: 12 | G9: 5 | H9: 7 | I9: 6 | J9: 21 | K9: =F9/D9 -> 0.5 | L9: =G9/D9 -> 0.20833333333333334 | M9: =H9/D9 -> 0.2916666666666667 | N9: =I9/C9 -> 0.2222222222222222 | O9: =J9/C9 -> 0.7777777777777778
A10: 강지호 | B10: 예시 인천남동경찰서 | C10: 27 | D10: 25 | E10: 2 | F10: 7 | G10: 6 | H10: 12 | I10: 7 | J10: 20 | K10: =F10/D10 -> 0.28 | L10: =G10/D10 -> 0.24 | M10: =H10/D10 -> 0.48 | N10: =I10/C10 -> 0.25925925925925924 | O10: =J10/C10 -> 0.7407407407407407
A11: 최민준 | B11: 예시 강남구청 | C11: 19 | D11: 17 | E11: 2 | F11: 11 | G11: 2 | H11: 4 | I11: 5 | J11: 14 | K11: =F11/D11 -> 0.6470588235294118 | L11: =G11/D11 -> 0.11764705882352941 | M11: =H11/D11 -> 0.23529411764705882 | N11: =I11/C11 -> 0.2631578947368421 | O11: =J11/C11 -> 0.7368421052631579
A12: 윤서아 | B12: 예시 대전서구청 | C12: 17 | D12: 16 | E12: 1 | F12: 9 | G12: 2 | H12: 5 | I12: 5 | J12: 12 | K12: =F12/D12 -> 0.5625 | L12: =G12/D12 -> 0.125 | M12: =H12/D12 -> 0.3125 | N12: =I12/C12 -> 0.29411764705882354 | O12: =J12/C12 -> 0.7058823529411765
A13: 서지안 | B13: 예시 부산연제경찰서 | C13: 17 | D13: 14 | E13: 3 | F13: 8 | G13: 1 | H13: 5 | I13: 2 | J13: 15 | K13: =F13/D13 -> 0.5714285714285714 | L13: =G13/D13 -> 0.07142857142857142 | M13: =H13/D13 -> 0.35714285714285715 | N13: =I13/C13 -> 0.11764705882352941 | O13: =J13/C13 -> 0.8823529411764706
A14: 김하늘 (수원시청) | B14: 예시 수원시청 | C14: 16 | D14: 14 | E14: 2 | F14: 8 | G14: 2 | H14: 4 | I14: 4 | J14: 12 | K14: =F14/D14 -> 0.5714285714285714 | L14: =G14/D14 -> 0.14285714285714285 | M14: =H14/D14 -> 0.2857142857142857 | N14: =I14/C14 -> 0.25 | O14: =J14/C14 -> 0.75
A15: 임준서 | B15: 예시 대구수성경찰서 | C15: 15 | D15: 13 | E15: 2 | F15: 7 | G15: 3 | H15: 3 | I15: 4 | J15: 11 | K15: =F15/D15 -> 0.5384615384615384 | L15: =G15/D15 -> 0.23076923076923078 | M15: =H15/D15 -> 0.23076923076923078 | N15: =I15/C15 -> 0.26666666666666666 | O15: =J15/C15 -> 0.7333333333333333
A16: 신우진 | B16: 예시 해운대구청 | C16: 15 | D16: 14 | E16: 1 | F16: 8 | G16: 2 | H16: 4 | I16: 5 | J16: 10 | K16: =F16/D16 -> 0.5714285714285714 | L16: =G16/D16 -> 0.14285714285714285 | M16: =H16/D16 -> 0.2857142857142857 | N16: =I16/C16 -> 0.3333333333333333 | O16: =J16/C16 -> 0.6666666666666666
A17: 오예린 | B17: 예시 광주북구청 | C17: 14 | D17: 10 | E17: 4 | F17: 6 | G17: 2 | H17: 2 | I17: 4 | J17: 10 | K17: =F17/D17 -> 0.6 | L17: =G17/D17 -> 0.2 | M17: =H17/D17 -> 0.2 | N17: =I17/C17 -> 0.2857142857142857 | O17: =J17/C17 -> 0.7142857142857143
... A23: 합성담당003 | B23: 예시 대구수성경찰서 | C23: 1 | D23: 1 | E23: 0 | F23: 0 | G23: 0 | H23: 1 | I23: 0 | J23: 1 | K23: =F23/D23 -> 0 | L23: =G23/D23 -> 0 | M23: =H23/D23 -> 1 | N23: =I23/C23 -> 0 | O23: =J23/C23 -> 1
A24: 합성담당004 | B24: 예시 대구수성경찰서 | C24: 1 | D24: 0 | E24: 1 | F24: 0 | G24: 0 | H24: 0 | I24: 1 | J24: 0 | K24: 계산 불가 | L24: 계산 불가 | M24: 계산 불가 | N24: =I24/C24 -> 1 | O24: =J24/C24 -> 0
A25: 합성담당005 | B25: 예시 대구수성경찰서 | C25: 1 | D25: 1 | E25: 0 | F25: 1 | G25: 0 | H25: 0 | I25: 0 | J25: 1 | K25: =F25/D25 -> 1 | L25: =G25/D25 -> 0 | M25: =H25/D25 -> 0 | N25: =I25/C25 -> 0 | O25: =J25/C25 -> 1
A26: 합성담당006 | B26: 예시 대구수성경찰서 | C26: 1 | D26: 1 | E26: 0 | F26: 0 | G26: 1 | H26: 0 | I26: 0 | J26: 1 | K26: =F26/D26 -> 0 | L26: =G26/D26 -> 1 | M26: =H26/D26 -> 0 | N26: =I26/C26 -> 0 | O26: =J26/C26 -> 1
A27: 합성담당007 | B27: 예시 대구수성경찰서 | C27: 1 | D27: 1 | E27: 0 | F27: 0 | G27: 0 | H27: 1 | I27: 1 | J27: 0 | K27: =F27/D27 -> 0 | L27: =G27/D27 -> 0 | M27: =H27/D27 -> 1 | N27: =I27/C27 -> 1 | O27: =J27/C27 -> 0
A28: 합성담당008 | B28: 예시 대구수성경찰서 | C28: 1 | D28: 0 | E28: 1 | F28: 0 | G28: 0 | H28: 0 | I28: 0 | J28: 1 | K28: 계산 불가 | L28: 계산 불가 | M28: 계산 불가 | N28: =I28/C28 -> 0 | O28: =J28/C28 -> 1
A29: 합성담당009 | B29: 예시 대구수성경찰서 | C29: 1 | D29: 1 | E29: 0 | F29: 1 | G29: 0 | H29: 0 | I29: 0 | J29: 1 | K29: =F29/D29 -> 1 | L29: =G29/D29 -> 0 | M29: =H29/D29 -> 0 | N29: =I29/C29 -> 0 | O29: =J29/C29 -> 1
A30: 합성담당010 | B30: 예시 대구수성경찰서 | C30: 1 | D30: 1 | E30: 0 | F30: 0 | G30: 1 | H30: 0 | I30: 1 | J30: 0 | K30: =F30/D30 -> 0 | L30: =G30/D30 -> 1 | M30: =H30/D30 -> 0 | N30: =I30/C30 -> 1 | O30: =J30/C30 -> 0
A31: 합성담당011 | B31: 예시 대구수성경찰서 | C31: 1 | D31: 1 | E31: 0 | F31: 0 | G31: 0 | H31: 1 | I31: 0 | J31: 1 | K31: =F31/D31 -> 0 | L31: =G31/D31 -> 0 | M31: =H31/D31 -> 1 | N31: =I31/C31 -> 0 | O31: =J31/C31 -> 1
A32: 합성담당012 | B32: 예시 대구수성경찰서 | C32: 1 | D32: 0 | E32: 1 | F32: 0 | G32: 0 | H32: 0 | I32: 0 | J32: 1 | K32: 계산 불가 | L32: 계산 불가 | M32: 계산 불가 | N32: =I32/C32 -> 0 | O32: =J32/C32 -> 1
A33: 합성담당013 | B33: 예시 대구수성경찰서 | C33: 1 | D33: 1 | E33: 0 | F33: 1 | G33: 0 | H33: 0 | I33: 1 | J33: 0 | K33: =F33/D33 -> 1 | L33: =G33/D33 -> 0 | M33: =H33/D33 -> 0 | N33: =I33/C33 -> 1 | O33: =J33/C33 -> 0
A34: 합성담당014 | B34: 예시 대구수성경찰서 | C34: 1 | D34: 1 | E34: 0 | F34: 0 | G34: 1 | H34: 0 | I34: 0 | J34: 1 | K34: =F34/D34 -> 0 | L34: =G34/D34 -> 1 | M34: =H34/D34 -> 0 | N34: =I34/C34 -> 0 | O34: =J34/C34 -> 1
A35: 합성담당015 | B35: 예시 대구수성경찰서 | C35: 1 | D35: 1 | E35: 0 | F35: 0 | G35: 0 | H35: 1 | I35: 0 | J35: 1 | K35: =F35/D35 -> 0 | L35: =G35/D35 -> 0 | M35: =H35/D35 -> 1 | N35: =I35/C35 -> 0 | O35: =J35/C35 -> 1
A36: 합성담당016 | B36: 예시 대구수성경찰서 | C36: 1 | D36: 0 | E36: 1 | F36: 0 | G36: 0 | H36: 0 | I36: 1 | J36: 0 | K36: 계산 불가 | L36: 계산 불가 | M36: 계산 불가 | N36: =I36/C36 -> 1 | O36: =J36/C36 -> 0
A37: 합성담당017 | B37: 예시 대구수성경찰서 | C37: 1 | D37: 1 | E37: 0 | F37: 1 | G37: 0 | H37: 0 | I37: 0 | J37: 1 | K37: =F37/D37 -> 1 | L37: =G37/D37 -> 0 | M37: =H37/D37 -> 0 | N37: =I37/C37 -> 0 | O37: =J37/C37 -> 1
A38: 합성담당018 | B38: 예시 대구수성경찰서 | C38: 1 | D38: 1 | E38: 0 | F38: 0 | G38: 1 | H38: 0 | I38: 0 | J38: 1 | K38: =F38/D38 -> 0 | L38: =G38/D38 -> 1 | M38: =H38/D38 -> 0 | N38: =I38/C38 -> 0 | O38: =J38/C38 -> 1
A39: 합성담당019 | B39: 예시 대구수성경찰서 | C39: 1 | D39: 1 | E39: 0 | F39: 0 | G39: 0 | H39: 1 | I39: 1 | J39: 0 | K39: =F39/D39 -> 0 | L39: =G39/D39 -> 0 | M39: =H39/D39 -> 1 | N39: =I39/C39 -> 1 | O39: =J39/C39 -> 0
A40: 합성담당020 | B40: 예시 대구수성경찰서 | C40: 1 | D40: 0 | E40: 1 | F40: 0 | G40: 0 | H40: 0 | I40: 0 | J40: 1 | K40: 계산 불가 | L40: 계산 불가 | M40: 계산 불가 | N40: =I40/C40 -> 0 | O40: =J40/C40 -> 1
A41: 합성담당021 | B41: 예시 대구수성경찰서 | C41: 1 | D41: 1 | E41: 0 | F41: 1 | G41: 0 | H41: 0 | I41: 0 | J41: 1 | K41: =F41/D41 -> 1 | L41: =G41/D41 -> 0 | M41: =H41/D41 -> 0 | N41: =I41/C41 -> 0 | O41: =J41/C41 -> 1
A42: 합성담당022 | B42: 예시 대구수성경찰서 | C42: 1 | D42: 1 | E42: 0 | F42: 0 | G42: 1 | H42: 0 | I42: 1 | J42: 0 | K42: =F42/D42 -> 0 | L42: =G42/D42 -> 1 | M42: =H42/D42 -> 0 | N42: =I42/C42 -> 1 | O42: =J42/C42 -> 0
A43: 합성담당023 | B43: 예시 대구수성경찰서 | C43: 1 | D43: 1 | E43: 0 | F43: 0 | G43: 0 | H43: 1 | I43: 0 | J43: 1 | K43: =F43/D43 -> 0 | L43: =G43/D43 -> 0 | M43: =H43/D43 -> 1 | N43: =I43/C43 -> 0 | O43: =J43/C43 -> 1
A44: 합성담당024 | B44: 예시 대구수성경찰서 | C44: 1 | D44: 0 | E44: 1 | F44: 0 | G44: 0 | H44: 0 | I44: 0 | J44: 1 | K44: 계산 불가 | L44: 계산 불가 | M44: 계산 불가 | N44: =I44/C44 -> 0 | O44: =J44/C44 -> 1
A45: 합성담당025 | B45: 예시 대구수성경찰서 | C45: 1 | D45: 1 | E45: 0 | F45: 1 | G45: 0 | H45: 0 | I45: 1 | J45: 0 | K45: =F45/D45 -> 1 | L45: =G45/D45 -> 0 | M45: =H45/D45 -> 0 | N45: =I45/C45 -> 1 | O45: =J45/C45 -> 0
A46: 합성담당026 | B46: 예시 대구수성경찰서 | C46: 1 | D46: 1 | E46: 0 | F46: 0 | G46: 1 | H46: 0 | I46: 0 | J46: 1 | K46: =F46/D46 -> 0 | L46: =G46/D46 -> 1 | M46: =H46/D46 -> 0 | N46: =I46/C46 -> 0 | O46: =J46/C46 -> 1
...

Sheet 차트
A1: 이 범위의 담당자별 처리 현황 · 차트
A3: 담당자별 수용률 (1–40 / 100)
A4: 선은 답변 완료 건수(오른쪽 축)입니다. 담당자가 많아 40명씩 나눠 그렸습니다.
A25: 담당자별 수용률 (41–80 / 100)
A26: 선은 답변 완료 건수(오른쪽 축)입니다. 담당자가 많아 40명씩 나눠 그렸습니다.
A47: 담당자별 수용률 (81–100 / 100)
A48: 선은 답변 완료 건수(오른쪽 축)입니다. 담당자가 많아 40명씩 나눠 그렸습니다.

Sheet 차트 데이터
A1: 차트 데이터
A2: 차트가 그리는 숫자입니다. ‘통계표’ 시트에서 가져옵니다.
A4: 담당자별 수용률 (1–40 / 100)
A5: 담당자 | B5: 수용 | C5: 일부수용 | D5: 불수용 | E5: 답변 완료(건, 오른쪽 축)
A6: 김하늘 (서울중부경찰서) | B6: ='통계표'!$K$6 -> 0.6551724137931034 | C6: ='통계표'!$L$6 -> 0.20689655172413793 | D6: ='통계표'!$M$6 -> 0.13793103448275862 | E6: ='통계표'!$C$6 -> 37
A7: 정하은 | B7: ='통계표'!$K$7 -> 0.6666666666666666 | C7: ='통계표'!$L$7 -> 0.1 | D7: ='통계표'!$M$7 -> 0.23333333333333334 | E7: ='통계표'!$C$7 -> 35
A8: 이서윤 | B8: ='통계표'!$K$8 -> 0.7333333333333333 | C8: ='통계표'!$L$8 -> 0.03333333333333333 | D8: ='통계표'!$M$8 -> 0.23333333333333334 | E8: ='통계표'!$C$8 -> 34
A9: 박도윤 | B9: ='통계표'!$K$9 -> 0.5 | C9: ='통계표'!$L$9 -> 0.20833333333333334 | D9: ='통계표'!$M$9 -> 0.2916666666666667 | E9: ='통계표'!$C$9 -> 27
A10: 강지호 | B10: ='통계표'!$K$10 -> 0.28 | C10: ='통계표'!$L$10 -> 0.24 | D10: ='통계표'!$M$10 -> 0.48 | E10: ='통계표'!$C$10 -> 27
A11: 최민준 | B11: ='통계표'!$K$11 -> 0.6470588235294118 | C11: ='통계표'!$L$11 -> 0.11764705882352941 | D11: ='통계표'!$M$11 -> 0.23529411764705882 | E11: ='통계표'!$C$11 -> 19
A12: 윤서아 | B12: ='통계표'!$K$12 -> 0.5625 | C12: ='통계표'!$L$12 -> 0.125 | D12: ='통계표'!$M$12 -> 0.3125 | E12: ='통계표'!$C$12 -> 17
A13: 서지안 | B13: ='통계표'!$K$13 -> 0.5714285714285714 | C13: ='통계표'!$L$13 -> 0.07142857142857142 | D13: ='통계표'!$M$13 -> 0.35714285714285715 | E13: ='통계표'!$C$13 -> 17
A14: 김하늘 (수원시청) | B14: ='통계표'!$K$14 -> 0.5714285714285714 | C14: ='통계표'!$L$14 -> 0.14285714285714285 | D14: ='통계표'!$M$14 -> 0.2857142857142857 | E14: ='통계표'!$C$14 -> 16
A15: 임준서 | B15: ='통계표'!$K$15 -> 0.5384615384615384 | C15: ='통계표'!$L$15 -> 0.23076923076923078 | D15: ='통계표'!$M$15 -> 0.23076923076923078 | E15: ='통계표'!$C$15 -> 15
A16: 신우진 | B16: ='통계표'!$K$16 -> 0.5714285714285714 | C16: ='통계표'!$L$16 -> 0.14285714285714285 | D16: ='통계표'!$M$16 -> 0.2857142857142857 | E16: ='통계표'!$C$16 -> 15
A17: 오예린 | B17: ='통계표'!$K$17 -> 0.6 | C17: ='통계표'!$L$17 -> 0.2 | D17: ='통계표'!$M$17 -> 0.2 | E17: ='통계표'!$C$17 -> 14
A18: 양시우 | B18: ='통계표'!$K$18 -> 0.8181818181818182 | C18: ='통계표'!$L$18 -> 0.09090909090909091 | D18: ='통계표'!$M$18 -> 0.09090909090909091 | E18: ='통계표'!$C$18 -> 14
A19: 한지우 | B19: ='통계표'!$K$19 -> 0.8333333333333334 | C19: ='통계표'!$L$19 -> 0 | D19: ='통계표'!$M$19 -> 0.16666666666666666 | E19: ='통계표'!$C$19 -> 6
A20: 문채원 | B20: ='통계표'!$K$20 -> 0.8 | C20: ='통계표'!$L$20 -> 0.2 | D20: ='통계표'!$M$20 -> 0 | E20: ='통계표'!$C$20 -> 5
A21: 합성담당001 | B21: ='통계표'!$K$21 -> 1 | C21: ='통계표'!$L$21 -> 0 | D21: ='통계표'!$M$21 -> 0 | E21: ='통계표'!$C$21 -> 1
A22: 합성담당002 | B22: ='통계표'!$K$22 -> 0 | C22: ='통계표'!$L$22 -> 1 | D22: ='통계표'!$M$22 -> 0 | E22: ='통계표'!$C$22 -> 1
A23: 합성담당003 | B23: ='통계표'!$K$23 -> 0 | C23: ='통계표'!$L$23 -> 0 | D23: ='통계표'!$M$23 -> 1 | E23: ='통계표'!$C$23 -> 1
A24: 합성담당004 | E24: ='통계표'!$C$24 -> 1
A25: 합성담당005 | B25: ='통계표'!$K$25 -> 1 | C25: ='통계표'!$L$25 -> 0 | D25: ='통계표'!$M$25 -> 0 | E25: ='통계표'!$C$25 -> 1
A26: 합성담당006 | B26: ='통계표'!$K$26 -> 0 | C26: ='통계표'!$L$26 -> 1 | D26: ='통계표'!$M$26 -> 0 | E26: ='통계표'!$C$26 -> 1
A27: 합성담당007 | B27: ='통계표'!$K$27 -> 0 | C27: ='통계표'!$L$27 -> 0 | D27: ='통계표'!$M$27 -> 1 | E27: ='통계표'!$C$27 -> 1
A28: 합성담당008 | E28: ='통계표'!$C$28 -> 1
A29: 합성담당009 | B29: ='통계표'!$K$29 -> 1 | C29: ='통계표'!$L$29 -> 0 | D29: ='통계표'!$M$29 -> 0 | E29: ='통계표'!$C$29 -> 1
A30: 합성담당010 | B30: ='통계표'!$K$30 -> 0 | C30: ='통계표'!$L$30 -> 1 | D30: ='통계표'!$M$30 -> 0 | E30: ='통계표'!$C$30 -> 1
A31: 합성담당011 | B31: ='통계표'!$K$31 -> 0 | C31: ='통계표'!$L$31 -> 0 | D31: ='통계표'!$M$31 -> 1 | E31: ='통계표'!$C$31 -> 1
A32: 합성담당012 | E32: ='통계표'!$C$32 -> 1
A33: 합성담당013 | B33: ='통계표'!$K$33 -> 1 | C33: ='통계표'!$L$33 -> 0 | D33: ='통계표'!$M$33 -> 0 | E33: ='통계표'!$C$33 -> 1
A34: 합성담당014 | B34: ='통계표'!$K$34 -> 0 | C34: ='통계표'!$L$34 -> 1 | D34: ='통계표'!$M$34 -> 0 | E34: ='통계표'!$C$34 -> 1
A35: 합성담당015 | B35: ='통계표'!$K$35 -> 0 | C35: ='통계표'!$L$35 -> 0 | D35: ='통계표'!$M$35 -> 1 | E35: ='통계표'!$C$35 -> 1
A36: 합성담당016 | E36: ='통계표'!$C$36 -> 1
A37: 합성담당017 | B37: ='통계표'!$K$37 -> 1 | C37: ='통계표'!$L$37 -> 0 | D37: ='통계표'!$M$37 -> 0 | E37: ='통계표'!$C$37 -> 1
A38: 합성담당018 | B38: ='통계표'!$K$38 -> 0 | C38: ='통계표'!$L$38 -> 1 | D38: ='통계표'!$M$38 -> 0 | E38: ='통계표'!$C$38 -> 1
A39: 합성담당019 | B39: ='통계표'!$K$39 -> 0 | C39: ='통계표'!$L$39 -> 0 | D39: ='통계표'!$M$39 -> 1 | E39: ='통계표'!$C$39 -> 1
A40: 합성담당020 | E40: ='통계표'!$C$40 -> 1
A41: 합성담당021 | B41: ='통계표'!$K$41 -> 1 | C41: ='통계표'!$L$41 -> 0 | D41: ='통계표'!$M$41 -> 0 | E41: ='통계표'!$C$41 -> 1
...

Sheet 조회 조건
A1: 이 범위의 담당자별 처리 현황 · 조회 조건
A3: 내려받은 시각 | B3: 2026-10-04 00:35:08 (한국 시간)
A4: 자료 버전 | B4: e2e-synthetic-1
A5: 날짜 기준 | B5: 답변일
A6: 기간 | B6: 2025-10-05 — 2026-10-04 · 일부 기간: 첫 달은 2025.10.05부터, 마지막 달은 2026.10.04까지
A7: 자료 버전 | B7: e2e-synthetic-1
A8: 대상 범위 | B8: 전국 · 모든 분류
A9: 담당자 | B9: 불러온 100명 (전체 125명)
A10: 막대 기준 | B10: 수용률 ((수용+일부수용+불수용)를 100%로)
A11: 계산 방법 | B11: 수용률·일부수용률·불수용률은 (수용+일부수용+불수용) 중 비율, 과태료 부과율은 전체 답변 중 과태료 처분의 비율입니다. 미분류는 안전신문고 처리 상태가 ‘답변완료’·‘기타’라 수용 여부가 없는 답변입니다.
A12: 이 파일에 대해 | B12: 내려받은 시점의 결과입니다.
